Traceback (most recent call last):
  File "/data/data/com.termux/files/usr/lib/python3.12/site-packages/urllib3/connectionpool.py", line 787, in urlopen
    response = self._make_request(
               ^^^^^^^^^^^^^^^^^^^
  File "/data/data/com.termux/files/usr/lib/python3.12/site-packages/urllib3/connectionpool.py", line 534, in _make_request
    response = conn.getresponse()
               ^^^^^^^^^^^^^^^^^^
  File "/data/data/com.termux/files/usr/lib/python3.12/site-packages/urllib3/connection.py", line 565, in getresponse
    httplib_response = super().getresponse()
                       ^^^^^^^^^^^^^^^^^^^^^
  File "/data/data/com.termux/files/usr/lib/python3.12/http/client.py", line 1430, in getresponse
    response.begin()
  File "/data/data/com.termux/files/usr/lib/python3.12/http/client.py", line 331, in begin
    version, status, reason = self._read_status()
                              ^^^^^^^^^^^^^^^^^^^
  File "/data/data/com.termux/files/usr/lib/python3.12/http/client.py", line 300, in _read_status
    raise RemoteDisconnected("Remote end closed connection without"
http.client.RemoteDisconnected: Remote end closed connection without response

During handling of the above exception, another exception occurred:

Traceback (most recent call last):
  File "/data/data/com.termux/files/usr/lib/python3.12/site-packages/requests/adapters.py", line 667, in send
    resp = conn.urlopen(
           ^^^^^^^^^^^^^
  File "/data/data/com.termux/files/usr/lib/python3.12/site-packages/urllib3/connectionpool.py", line 841, in urlopen
    retries = retries.increment(
              ^^^^^^^^^^^^^^^^^^
  File "/data/data/com.termux/files/usr/lib/python3.12/site-packages/urllib3/util/retry.py", line 474, in increment
    raise reraise(type(error), error, _stacktrace)
          ^^^^^^^^^^^^^^^^^^^^^^^^^^^^^^^^^^^^^^^^
  File "/data/data/com.termux/files/usr/lib/python3.12/site-packages/urllib3/util/util.py", line 38, in reraise
    raise value.with_traceback(tb)
  File "/data/data/com.termux/files/usr/lib/python3.12/site-packages/urllib3/connectionpool.py", line 787, in urlopen
    response = self._make_request(
               ^^^^^^^^^^^^^^^^^^^
  File "/data/data/com.termux/files/usr/lib/python3.12/site-packages/urllib3/connectionpool.py", line 534, in _make_request
    response = conn.getresponse()
               ^^^^^^^^^^^^^^^^^^
  File "/data/data/com.termux/files/usr/lib/python3.12/site-packages/urllib3/connection.py", line 565, in getresponse
    httplib_response = super().getresponse()
                       ^^^^^^^^^^^^^^^^^^^^^
  File "/data/data/com.termux/files/usr/lib/python3.12/http/client.py", line 1430, in getresponse
    response.begin()
  File "/data/data/com.termux/files/usr/lib/python3.12/http/client.py", line 331, in begin
    version, status, reason = self._read_status()
                              ^^^^^^^^^^^^^^^^^^^
  File "/data/data/com.termux/files/usr/lib/python3.12/http/client.py", line 300, in _read_status
    raise RemoteDisconnected("Remote end closed connection without"
urllib3.exceptions.ProtocolError: ('Connection aborted.', RemoteDisconnected('Remote end closed connection without response'))

During handling of the above exception, another exception occurred:

Traceback (most recent call last):
  File "/storage/emulated/0/Download/telegram_bot/bot.py", line 36, in <module>
    bot.polling()
  File "/data/data/com.termux/files/usr/lib/python3.12/site-packages/telebot/__init__.py", line 1198, in polling
    self.__threaded_polling(non_stop=non_stop, interval=interval, timeout=timeout, long_polling_timeout=long_polling_timeout,
  File "/data/data/com.termux/files/usr/lib/python3.12/site-packages/telebot/__init__.py", line 1273, in __threaded_polling
    raise e
  File "/data/data/com.termux/files/usr/lib/python3.12/site-packages/telebot/__init__.py", line 1234, in __threaded_polling
    polling_thread.raise_exceptions()
  File "/data/data/com.termux/files/usr/lib/python3.12/site-packages/telebot/util.py", line 111, in raise_exceptions
    raise self.exception_info
  File "/data/data/com.termux/files/usr/lib/python3.12/site-packages/telebot/util.py", line 93, in run
    task(*args, **kwargs)
  File "/data/data/com.termux/files/usr/lib/python3.12/site-packages/telebot/__init__.py", line 688, in __retrieve_updates
    updates = self.get_updates(offset=(self.last_update_id + 1), 
              ^^^^^^^^^^^^^^^^^^^^^^^^^^^^^^^^^^^^^^^^^^^^^^^^^^
  File "/data/data/com.termux/files/usr/lib/python3.12/site-packages/telebot/__init__.py", line 660, in get_updates
    json_updates = apihelper.get_updates(
                   ^^^^^^^^^^^^^^^^^^^^^^
  File "/data/data/com.termux/files/usr/lib/python3.12/site-packages/telebot/apihelper.py", line 332, in get_updates
    return _make_request(token, method_url, params=payload)
           ^^^^^^^^^^^^^^^^^^^^^^^^^^^^^^^^^^^^^^^^^^^^^^^^
  File "/data/data/com.termux/files/usr/lib/python3.12/site-packages/telebot/apihelper.py", line 162, in _make_request
    result = _get_req_session().request(
             ^^^^^^^^^^^^^^^^^^^^^^^^^^^
  File "/data/data/com.termux/files/usr/lib/python3.12/site-packages/requests/sessions.py", line 589, in request
    resp = self.send(prep, **send_kwargs)
           ^^^^^^^^^^^^^^^^^^^^^^^^^^^^^^
  File "/data/data/com.termux/files/usr/lib/python3.12/site-packages/requests/sessions.py", line 703, in send
    r = adapter.send(request, **kwargs)
        ^^^^^^^^^^^^^^^^^^^^^^^^^^^^^^^
  File "/data/data/com.termux/files/usr/lib/python3.12/site-packages/requests/adapters.py", line 682, in send
    raise ConnectionError(err, request=request)
requests.exceptions.ConnectionError: ('Connection aborted.', RemoteDisconnected('Remote end closed connection without response'))
Traceback (most recent call last):
  File "/data/data/com.termux/files/usr/lib/python3.12/site-packages/urllib3/connectionpool.py", line 787, in urlopen
    response = self._make_request(
               ^^^^^^^^^^^^^^^^^^^
  File "/data/data/com.termux/files/usr/lib/python3.12/site-packages/urllib3/connectionpool.py", line 534, in _make_request
    response = conn.getresponse()
               ^^^^^^^^^^^^^^^^^^
  File "/data/data/com.termux/files/usr/lib/python3.12/site-packages/urllib3/connection.py", line 565, in getresponse
    httplib_response = super().getresponse()
                       ^^^^^^^^^^^^^^^^^^^^^
  File "/data/data/com.termux/files/usr/lib/python3.12/http/client.py", line 1430, in getresponse
    response.begin()
  File "/data/data/com.termux/files/usr/lib/python3.12/http/client.py", line 331, in begin
    version, status, reason = self._read_status()
                              ^^^^^^^^^^^^^^^^^^^
  File "/data/data/com.termux/files/usr/lib/python3.12/http/client.py", line 300, in _read_status
    raise RemoteDisconnected("Remote end closed connection without"
http.client.RemoteDisconnected: Remote end closed connection without response

During handling of the above exception, another exception occurred:

Traceback (most recent call last):
  File "/data/data/com.termux/files/usr/lib/python3.12/site-packages/requests/adapters.py", line 667, in send
    resp = conn.urlopen(
           ^^^^^^^^^^^^^
  File "/data/data/com.termux/files/usr/lib/python3.12/site-packages/urllib3/connectionpool.py", line 841, in urlopen
    retries = retries.increment(
              ^^^^^^^^^^^^^^^^^^
  File "/data/data/com.termux/files/usr/lib/python3.12/site-packages/urllib3/util/retry.py", line 474, in increment
    raise reraise(type(error), error, _stacktrace)
          ^^^^^^^^^^^^^^^^^^^^^^^^^^^^^^^^^^^^^^^^
  File "/data/data/com.termux/files/usr/lib/python3.12/site-packages/urllib3/util/util.py", line 38, in reraise
    raise value.with_traceback(tb)
  File "/data/data/com.termux/files/usr/lib/python3.12/site-packages/urllib3/connectionpool.py", line 787, in urlopen
    response = self._make_request(
               ^^^^^^^^^^^^^^^^^^^
  File "/data/data/com.termux/files/usr/lib/python3.12/site-packages/urllib3/connectionpool.py", line 534, in _make_request
    response = conn.getresponse()
               ^^^^^^^^^^^^^^^^^^
  File "/data/data/com.termux/files/usr/lib/python3.12/site-packages/urllib3/connection.py", line 565, in getresponse
    httplib_response = super().getresponse()
                       ^^^^^^^^^^^^^^^^^^^^^
  File "/data/data/com.termux/files/usr/lib/python3.12/http/client.py", line 1430, in getresponse
    response.begin()
  File "/data/data/com.termux/files/usr/lib/python3.12/http/client.py", line 331, in begin
    version, status, reason = self._read_status()
                              ^^^^^^^^^^^^^^^^^^^
  File "/data/data/com.termux/files/usr/lib/python3.12/http/client.py", line 300, in _read_status
    raise RemoteDisconnected("Remote end closed connection without"
urllib3.exceptions.ProtocolError: ('Connection aborted.', RemoteDisconnected('Remote end closed connection without response'))

During handling of the above exception, another exception occurred:

Traceback (most recent call last):
  File "/storage/emulated/0/Download/telegram_bot/bot.py", line 36, in <module>
    bot.polling()
  File "/data/data/com.termux/files/usr/lib/python3.12/site-packages/telebot/__init__.py", line 1198, in polling
    self.__threaded_polling(non_stop=non_stop, interval=interval, timeout=timeout, long_polling_timeout=long_polling_timeout,
  File "/data/data/com.termux/files/usr/lib/python3.12/site-packages/telebot/__init__.py", line 1273, in __threaded_polling
    raise e
  File "/data/data/com.termux/files/usr/lib/python3.12/site-packages/telebot/__init__.py", line 1234, in __threaded_polling
    polling_thread.raise_exceptions()
  File "/data/data/com.termux/files/usr/lib/python3.12/site-packages/telebot/util.py", line 111, in raise_exceptions
    raise self.exception_info
  File "/data/data/com.termux/files/usr/lib/python3.12/site-packages/telebot/util.py", line 93, in run
    task(*args, **kwargs)
  File "/data/data/com.termux/files/usr/lib/python3.12/site-packages/telebot/__init__.py", line 688, in __retrieve_updates
    updates = self.get_updates(offset=(self.last_update_id + 1), 
              ^^^^^^^^^^^^^^^^^^^^^^^^^^^^^^^^^^^^^^^^^^^^^^^^^^
  File "/data/data/com.termux/files/usr/lib/python3.12/site-packages/telebot/__init__.py", line 660, in get_updates
    json_updates = apihelper.get_updates(
                   ^^^^^^^^^^^^^^^^^^^^^^
  File "/data/data/com.termux/files/usr/lib/python3.12/site-packages/telebot/apihelper.py", line 332, in get_updates
    return _make_request(token, method_url, params=payload)
           ^^^^^^^^^^^^^^^^^^^^^^^^^^^^^^^^^^^^^^^^^^^^^^^^
  File "/data/data/com.termux/files/usr/lib/python3.12/site-packages/telebot/apihelper.py", line 162, in _make_request
    result = _get_req_session().request(
             ^^^^^^^^^^^^^^^^^^^^^^^^^^^
  File "/data/data/com.termux/files/usr/lib/python3.12/site-packages/requests/sessions.py", line 589, in request
    resp = self.send(prep, **send_kwargs)
           ^^^^^^^^^^^^^^^^^^^^^^^^^^^^^^
  File "/data/data/com.termux/files/usr/lib/python3.12/site-packages/requests/sessions.py", line 703, in send
    r = adapter.send(request, **kwargs)
        ^^^^^^^^^^^^^^^^^^^^^^^^^^^^^^^
  File "/data/data/com.termux/files/usr/lib/python3.12/site-packages/requests/adapters.py", line 682, in send
    raise ConnectionError(err, request=request)
requests.exceptions.ConnectionError: ('Connection aborted.', RemoteDisconnected('Remote end closed connection without response'))
Traceback (most recent call last):
  File "/data/data/com.termux/files/usr/lib/python3.12/site-packages/urllib3/connectionpool.py", line 787, in urlopen
    response = self._make_request(
               ^^^^^^^^^^^^^^^^^^^
  File "/data/data/com.termux/files/usr/lib/python3.12/site-packages/urllib3/connectionpool.py", line 534, in _make_request
    response = conn.getresponse()
               ^^^^^^^^^^^^^^^^^^
  File "/data/data/com.termux/files/usr/lib/python3.12/site-packages/urllib3/connection.py", line 565, in getresponse
    httplib_response = super().getresponse()
                       ^^^^^^^^^^^^^^^^^^^^^
  File "/data/data/com.termux/files/usr/lib/python3.12/http/client.py", line 1430, in getresponse
    response.begin()
  File "/data/data/com.termux/files/usr/lib/python3.12/http/client.py", line 331, in begin
    version, status, reason = self._read_status()
                              ^^^^^^^^^^^^^^^^^^^
  File "/data/data/com.termux/files/usr/lib/python3.12/http/client.py", line 300, in _read_status
    raise RemoteDisconnected("Remote end closed connection without"
http.client.RemoteDisconnected: Remote end closed connection without response

During handling of the above exception, another exception occurred:

Traceback (most recent call last):
  File "/data/data/com.termux/files/usr/lib/python3.12/site-packages/requests/adapters.py", line 667, in send
    resp = conn.urlopen(
           ^^^^^^^^^^^^^
  File "/data/data/com.termux/files/usr/lib/python3.12/site-packages/urllib3/connectionpool.py", line 841, in urlopen
    retries = retries.increment(
              ^^^^^^^^^^^^^^^^^^
  File "/data/data/com.termux/files/usr/lib/python3.12/site-packages/urllib3/util/retry.py", line 474, in increment
    raise reraise(type(error), error, _stacktrace)
          ^^^^^^^^^^^^^^^^^^^^^^^^^^^^^^^^^^^^^^^^
  File "/data/data/com.termux/files/usr/lib/python3.12/site-packages/urllib3/util/util.py", line 38, in reraise
    raise value.with_traceback(tb)
  File "/data/data/com.termux/files/usr/lib/python3.12/site-packages/urllib3/connectionpool.py", line 787, in urlopen
    response = self._make_request(
               ^^^^^^^^^^^^^^^^^^^
  File "/data/data/com.termux/files/usr/lib/python3.12/site-packages/urllib3/connectionpool.py", line 534, in _make_request
    response = conn.getresponse()
               ^^^^^^^^^^^^^^^^^^
  File "/data/data/com.termux/files/usr/lib/python3.12/site-packages/urllib3/connection.py", line 565, in getresponse
    httplib_response = super().getresponse()
                       ^^^^^^^^^^^^^^^^^^^^^
  File "/data/data/com.termux/files/usr/lib/python3.12/http/client.py", line 1430, in getresponse
    response.begin()
  File "/data/data/com.termux/files/usr/lib/python3.12/http/client.py", line 331, in begin
    version, status, reason = self._read_status()
                              ^^^^^^^^^^^^^^^^^^^
  File "/data/data/com.termux/files/usr/lib/python3.12/http/client.py", line 300, in _read_status
    raise RemoteDisconnected("Remote end closed connection without"
urllib3.exceptions.ProtocolError: ('Connection aborted.', RemoteDisconnected('Remote end closed connection without response'))

During handling of the above exception, another exception occurred:

Traceback (most recent call last):
  File "/storage/emulated/0/Download/telegram_bot/bot.py", line 37, in <module>
    bot.polling()
  File "/data/data/com.termux/files/usr/lib/python3.12/site-packages/telebot/__init__.py", line 1198, in polling
    self.__threaded_polling(non_stop=non_stop, interval=interval, timeout=timeout, long_polling_timeout=long_polling_timeout,
  File "/data/data/com.termux/files/usr/lib/python3.12/site-packages/telebot/__init__.py", line 1273, in __threaded_polling
    raise e
  File "/data/data/com.termux/files/usr/lib/python3.12/site-packages/telebot/__init__.py", line 1234, in __threaded_polling
    polling_thread.raise_exceptions()
  File "/data/data/com.termux/files/usr/lib/python3.12/site-packages/telebot/util.py", line 111, in raise_exceptions
    raise self.exception_info
  File "/data/data/com.termux/files/usr/lib/python3.12/site-packages/telebot/util.py", line 93, in run
    task(*args, **kwargs)
  File "/data/data/com.termux/files/usr/lib/python3.12/site-packages/telebot/__init__.py", line 688, in __retrieve_updates
    updates = self.get_updates(offset=(self.last_update_id + 1), 
              ^^^^^^^^^^^^^^^^^^^^^^^^^^^^^^^^^^^^^^^^^^^^^^^^^^
  File "/data/data/com.termux/files/usr/lib/python3.12/site-packages/telebot/__init__.py", line 660, in get_updates
    json_updates = apihelper.get_updates(
                   ^^^^^^^^^^^^^^^^^^^^^^
  File "/data/data/com.termux/files/usr/lib/python3.12/site-packages/telebot/apihelper.py", line 332, in get_updates
    return _make_request(token, method_url, params=payload)
           ^^^^^^^^^^^^^^^^^^^^^^^^^^^^^^^^^^^^^^^^^^^^^^^^
  File "/data/data/com.termux/files/usr/lib/python3.12/site-packages/telebot/apihelper.py", line 162, in _make_request
    result = _get_req_session().request(
             ^^^^^^^^^^^^^^^^^^^^^^^^^^^
  File "/data/data/com.termux/files/usr/lib/python3.12/site-packages/requests/sessions.py", line 589, in request
    resp = self.send(prep, **send_kwargs)
           ^^^^^^^^^^^^^^^^^^^^^^^^^^^^^^
  File "/data/data/com.termux/files/usr/lib/python3.12/site-packages/requests/sessions.py", line 703, in send
    r = adapter.send(request, **kwargs)
        ^^^^^^^^^^^^^^^^^^^^^^^^^^^^^^^
  File "/data/data/com.termux/files/usr/lib/python3.12/site-packages/requests/adapters.py", line 682, in send
    raise ConnectionError(err, request=request)
requests.exceptions.ConnectionError: ('Connection aborted.', RemoteDisconnected('Remote end closed connection without response'))
Traceback (most recent call last):
  File "/data/data/com.termux/files/usr/lib/python3.12/site-packages/urllib3/connectionpool.py", line 787, in urlopen
    response = self._make_request(
               ^^^^^^^^^^^^^^^^^^^
  File "/data/data/com.termux/files/usr/lib/python3.12/site-packages/urllib3/connectionpool.py", line 534, in _make_request
    response = conn.getresponse()
               ^^^^^^^^^^^^^^^^^^
  File "/data/data/com.termux/files/usr/lib/python3.12/site-packages/urllib3/connection.py", line 565, in getresponse
    httplib_response = super().getresponse()
                       ^^^^^^^^^^^^^^^^^^^^^
  File "/data/data/com.termux/files/usr/lib/python3.12/http/client.py", line 1430, in getresponse
    response.begin()
  File "/data/data/com.termux/files/usr/lib/python3.12/http/client.py", line 331, in begin
    version, status, reason = self._read_status()
                              ^^^^^^^^^^^^^^^^^^^
  File "/data/data/com.termux/files/usr/lib/python3.12/http/client.py", line 300, in _read_status
    raise RemoteDisconnected("Remote end closed connection without"
http.client.RemoteDisconnected: Remote end closed connection without response

During handling of the above exception, another exception occurred:

Traceback (most recent call last):
  File "/data/data/com.termux/files/usr/lib/python3.12/site-packages/requests/adapters.py", line 667, in send
    resp = conn.urlopen(
           ^^^^^^^^^^^^^
  File "/data/data/com.termux/files/usr/lib/python3.12/site-packages/urllib3/connectionpool.py", line 841, in urlopen
    retries = retries.increment(
              ^^^^^^^^^^^^^^^^^^
  File "/data/data/com.termux/files/usr/lib/python3.12/site-packages/urllib3/util/retry.py", line 474, in increment
    raise reraise(type(error), error, _stacktrace)
          ^^^^^^^^^^^^^^^^^^^^^^^^^^^^^^^^^^^^^^^^
  File "/data/data/com.termux/files/usr/lib/python3.12/site-packages/urllib3/util/util.py", line 38, in reraise
    raise value.with_traceback(tb)
  File "/data/data/com.termux/files/usr/lib/python3.12/site-packages/urllib3/connectionpool.py", line 787, in urlopen
    response = self._make_request(
               ^^^^^^^^^^^^^^^^^^^
  File "/data/data/com.termux/files/usr/lib/python3.12/site-packages/urllib3/connectionpool.py", line 534, in _make_request
    response = conn.getresponse()
               ^^^^^^^^^^^^^^^^^^
  File "/data/data/com.termux/files/usr/lib/python3.12/site-packages/urllib3/connection.py", line 565, in getresponse
    httplib_response = super().getresponse()
                       ^^^^^^^^^^^^^^^^^^^^^
  File "/data/data/com.termux/files/usr/lib/python3.12/http/client.py", line 1430, in getresponse
    response.begin()
  File "/data/data/com.termux/files/usr/lib/python3.12/http/client.py", line 331, in begin
    version, status, reason = self._read_status()
                              ^^^^^^^^^^^^^^^^^^^
  File "/data/data/com.termux/files/usr/lib/python3.12/http/client.py", line 300, in _read_status
    raise RemoteDisconnected("Remote end closed connection without"
urllib3.exceptions.ProtocolError: ('Connection aborted.', RemoteDisconnected('Remote end closed connection without response'))

During handling of the above exception, another exception occurred:

Traceback (most recent call last):
  File "/storage/emulated/0/Download/telegram_bot/bot.py", line 37, in <module>
    bot.polling()
  File "/data/data/com.termux/files/usr/lib/python3.12/site-packages/telebot/__init__.py", line 1198, in polling
    self.__threaded_polling(non_stop=non_stop, interval=interval, timeout=timeout, long_polling_timeout=long_polling_timeout,
  File "/data/data/com.termux/files/usr/lib/python3.12/site-packages/telebot/__init__.py", line 1273, in __threaded_polling
    raise e
  File "/data/data/com.termux/files/usr/lib/python3.12/site-packages/telebot/__init__.py", line 1234, in __threaded_polling
    polling_thread.raise_exceptions()
  File "/data/data/com.termux/files/usr/lib/python3.12/site-packages/telebot/util.py", line 111, in raise_exceptions
    raise self.exception_info
  File "/data/data/com.termux/files/usr/lib/python3.12/site-packages/telebot/util.py", line 93, in run
    task(*args, **kwargs)
  File "/data/data/com.termux/files/usr/lib/python3.12/site-packages/telebot/__init__.py", line 688, in __retrieve_updates
    updates = self.get_updates(offset=(self.last_update_id + 1), 
              ^^^^^^^^^^^^^^^^^^^^^^^^^^^^^^^^^^^^^^^^^^^^^^^^^^
  File "/data/data/com.termux/files/usr/lib/python3.12/site-packages/telebot/__init__.py", line 660, in get_updates
    json_updates = apihelper.get_updates(
                   ^^^^^^^^^^^^^^^^^^^^^^
  File "/data/data/com.termux/files/usr/lib/python3.12/site-packages/telebot/apihelper.py", line 332, in get_updates
    return _make_request(token, method_url, params=payload)
           ^^^^^^^^^^^^^^^^^^^^^^^^^^^^^^^^^^^^^^^^^^^^^^^^
  File "/data/data/com.termux/files/usr/lib/python3.12/site-packages/telebot/apihelper.py", line 162, in _make_request
    result = _get_req_session().request(
             ^^^^^^^^^^^^^^^^^^^^^^^^^^^
  File "/data/data/com.termux/files/usr/lib/python3.12/site-packages/requests/sessions.py", line 589, in request
    resp = self.send(prep, **send_kwargs)
           ^^^^^^^^^^^^^^^^^^^^^^^^^^^^^^
  File "/data/data/com.termux/files/usr/lib/python3.12/site-packages/requests/sessions.py", line 703, in send
    r = adapter.send(request, **kwargs)
        ^^^^^^^^^^^^^^^^^^^^^^^^^^^^^^^
  File "/data/data/com.termux/files/usr/lib/python3.12/site-packages/requests/adapters.py", line 682, in send
    raise ConnectionError(err, request=request)
requests.exceptions.ConnectionError: ('Connection aborted.', RemoteDisconnected('Remote end closed connection without response'))
python: can't open file '/storage/emulated/0/Download/telegram_bot/bot.': [Errno 2] No such file or directory
Traceback (most recent call last):
  File "/data/data/com.termux/files/usr/lib/python3.12/site-packages/urllib3/connectionpool.py", line 787, in urlopen
    response = self._make_request(
               ^^^^^^^^^^^^^^^^^^^
  File "/data/data/com.termux/files/usr/lib/python3.12/site-packages/urllib3/connectionpool.py", line 493, in _make_request
    conn.request(
  File "/data/data/com.termux/files/usr/lib/python3.12/site-packages/urllib3/connection.py", line 508, in request
    self.send(chunk)
  File "/data/data/com.termux/files/usr/lib/python3.12/http/client.py", line 1057, in send
    self.sock.sendall(data)
  File "/data/data/com.termux/files/usr/lib/python3.12/ssl.py", line 1210, in sendall
    v = self.send(byte_view[count:])
        ^^^^^^^^^^^^^^^^^^^^^^^^^^^^
  File "/data/data/com.termux/files/usr/lib/python3.12/ssl.py", line 1179, in send
    return self._sslobj.write(data)
           ^^^^^^^^^^^^^^^^^^^^^^^^
ConnectionAbortedError: [Errno 103] Software caused connection abort

During handling of the above exception, another exception occurred:

Traceback (most recent call last):
  File "/data/data/com.termux/files/usr/lib/python3.12/site-packages/requests/adapters.py", line 667, in send
    resp = conn.urlopen(
           ^^^^^^^^^^^^^
  File "/data/data/com.termux/files/usr/lib/python3.12/site-packages/urllib3/connectionpool.py", line 841, in urlopen
    retries = retries.increment(
              ^^^^^^^^^^^^^^^^^^
  File "/data/data/com.termux/files/usr/lib/python3.12/site-packages/urllib3/util/retry.py", line 474, in increment
    raise reraise(type(error), error, _stacktrace)
          ^^^^^^^^^^^^^^^^^^^^^^^^^^^^^^^^^^^^^^^^
  File "/data/data/com.termux/files/usr/lib/python3.12/site-packages/urllib3/util/util.py", line 38, in reraise
    raise value.with_traceback(tb)
  File "/data/data/com.termux/files/usr/lib/python3.12/site-packages/urllib3/connectionpool.py", line 787, in urlopen
    response = self._make_request(
               ^^^^^^^^^^^^^^^^^^^
  File "/data/data/com.termux/files/usr/lib/python3.12/site-packages/urllib3/connectionpool.py", line 493, in _make_request
    conn.request(
  File "/data/data/com.termux/files/usr/lib/python3.12/site-packages/urllib3/connection.py", line 508, in request
    self.send(chunk)
  File "/data/data/com.termux/files/usr/lib/python3.12/http/client.py", line 1057, in send
    self.sock.sendall(data)
  File "/data/data/com.termux/files/usr/lib/python3.12/ssl.py", line 1210, in sendall
    v = self.send(byte_view[count:])
        ^^^^^^^^^^^^^^^^^^^^^^^^^^^^
  File "/data/data/com.termux/files/usr/lib/python3.12/ssl.py", line 1179, in send
    return self._sslobj.write(data)
           ^^^^^^^^^^^^^^^^^^^^^^^^
urllib3.exceptions.ProtocolError: ('Connection aborted.', ConnectionAbortedError(103, 'Software caused connection abort'))

During handling of the above exception, another exception occurred:

Traceback (most recent call last):
  File "/data/data/com.termux/files/home/storage/downloads/telegram_bot/bot.py", line 37, in <module>
    bot.polling()
  File "/data/data/com.termux/files/usr/lib/python3.12/site-packages/telebot/__init__.py", line 1198, in polling
    self.__threaded_polling(non_stop=non_stop, interval=interval, timeout=timeout, long_polling_timeout=long_polling_timeout,
  File "/data/data/com.termux/files/usr/lib/python3.12/site-packages/telebot/__init__.py", line 1273, in __threaded_polling
    raise e
  File "/data/data/com.termux/files/usr/lib/python3.12/site-packages/telebot/__init__.py", line 1235, in __threaded_polling
    self.worker_pool.raise_exceptions()
  File "/data/data/com.termux/files/usr/lib/python3.12/site-packages/telebot/util.py", line 150, in raise_exceptions
    raise self.exception_info
  File "/data/data/com.termux/files/usr/lib/python3.12/site-packages/telebot/util.py", line 93, in run
    task(*args, **kwargs)
  File "/data/data/com.termux/files/usr/lib/python3.12/site-packages/telebot/__init__.py", line 9759, in _run_middlewares_and_handler
    result = handler['function'](message)
             ^^^^^^^^^^^^^^^^^^^^^^^^^^^^
  File "/data/data/com.termux/files/home/storage/downloads/telegram_bot/bot.py", line 14, in start
    bot.send_photo(message.chat.id, photo, caption="Привет! Я Манго бот!\n\n Я отправляю эдиты/долгие ролики про манго! команда /video чтобы получить эдит ~20сек, видео пока нет 40+сек. \n\n 		b.y 1123")
  File "/data/data/com.termux/files/usr/lib/python3.12/site-packages/telebot/__init__.py", line 2309, in send_photo
    apihelper.send_photo(
  File "/data/data/com.termux/files/usr/lib/python3.12/site-packages/telebot/apihelper.py", line 551, in send_photo
    return _make_request(token, method_url, params=payload, files=files, method='post')
           ^^^^^^^^^^^^^^^^^^^^^^^^^^^^^^^^^^^^^^^^^^^^^^^^^^^^^^^^^^^^^^^^^^^^^^^^^^^^
  File "/data/data/com.termux/files/usr/lib/python3.12/site-packages/telebot/apihelper.py", line 162, in _make_request
    result = _get_req_session().request(
             ^^^^^^^^^^^^^^^^^^^^^^^^^^^
  File "/data/data/com.termux/files/usr/lib/python3.12/site-packages/requests/sessions.py", line 589, in request
    resp = self.send(prep, **send_kwargs)
           ^^^^^^^^^^^^^^^^^^^^^^^^^^^^^^
  File "/data/data/com.termux/files/usr/lib/python3.12/site-packages/requests/sessions.py", line 703, in send
    r = adapter.send(request, **kwargs)
        ^^^^^^^^^^^^^^^^^^^^^^^^^^^^^^^
  File "/data/data/com.termux/files/usr/lib/python3.12/site-packages/requests/adapters.py", line 682, in send
    raise ConnectionError(err, request=request)
requests.exceptions.ConnectionError: ('Connection aborted.', ConnectionAbortedError(103, 'Software caused connection abort'))
Traceback (most recent call last):
  File "/data/data/com.termux/files/usr/lib/python3.12/site-packages/urllib3/connectionpool.py", line 787, in urlopen
    response = self._make_request(
               ^^^^^^^^^^^^^^^^^^^
  File "/data/data/com.termux/files/usr/lib/python3.12/site-packages/urllib3/connectionpool.py", line 534, in _make_request
    response = conn.getresponse()
               ^^^^^^^^^^^^^^^^^^
  File "/data/data/com.termux/files/usr/lib/python3.12/site-packages/urllib3/connection.py", line 565, in getresponse
    httplib_response = super().getresponse()
                       ^^^^^^^^^^^^^^^^^^^^^
  File "/data/data/com.termux/files/usr/lib/python3.12/http/client.py", line 1430, in getresponse
    response.begin()
  File "/data/data/com.termux/files/usr/lib/python3.12/http/client.py", line 331, in begin
    version, status, reason = self._read_status()
                              ^^^^^^^^^^^^^^^^^^^
  File "/data/data/com.termux/files/usr/lib/python3.12/http/client.py", line 300, in _read_status
    raise RemoteDisconnected("Remote end closed connection without"
http.client.RemoteDisconnected: Remote end closed connection without response

During handling of the above exception, another exception occurred:

Traceback (most recent call last):
  File "/data/data/com.termux/files/usr/lib/python3.12/site-packages/requests/adapters.py", line 667, in send
    resp = conn.urlopen(
           ^^^^^^^^^^^^^
  File "/data/data/com.termux/files/usr/lib/python3.12/site-packages/urllib3/connectionpool.py", line 841, in urlopen
    retries = retries.increment(
              ^^^^^^^^^^^^^^^^^^
  File "/data/data/com.termux/files/usr/lib/python3.12/site-packages/urllib3/util/retry.py", line 474, in increment
    raise reraise(type(error), error, _stacktrace)
          ^^^^^^^^^^^^^^^^^^^^^^^^^^^^^^^^^^^^^^^^
  File "/data/data/com.termux/files/usr/lib/python3.12/site-packages/urllib3/util/util.py", line 38, in reraise
    raise value.with_traceback(tb)
  File "/data/data/com.termux/files/usr/lib/python3.12/site-packages/urllib3/connectionpool.py", line 787, in urlopen
    response = self._make_request(
               ^^^^^^^^^^^^^^^^^^^
  File "/data/data/com.termux/files/usr/lib/python3.12/site-packages/urllib3/connectionpool.py", line 534, in _make_request
    response = conn.getresponse()
               ^^^^^^^^^^^^^^^^^^
  File "/data/data/com.termux/files/usr/lib/python3.12/site-packages/urllib3/connection.py", line 565, in getresponse
    httplib_response = super().getresponse()
                       ^^^^^^^^^^^^^^^^^^^^^
  File "/data/data/com.termux/files/usr/lib/python3.12/http/client.py", line 1430, in getresponse
    response.begin()
  File "/data/data/com.termux/files/usr/lib/python3.12/http/client.py", line 331, in begin
    version, status, reason = self._read_status()
                              ^^^^^^^^^^^^^^^^^^^
  File "/data/data/com.termux/files/usr/lib/python3.12/http/client.py", line 300, in _read_status
    raise RemoteDisconnected("Remote end closed connection without"
urllib3.exceptions.ProtocolError: ('Connection aborted.', RemoteDisconnected('Remote end closed connection without response'))

During handling of the above exception, another exception occurred:

Traceback (most recent call last):
  File "/data/data/com.termux/files/home/storage/downloads/telegram_bot/bot.py", line 37, in <module>
    bot.polling()
  File "/data/data/com.termux/files/usr/lib/python3.12/site-packages/telebot/__init__.py", line 1198, in polling
    self.__threaded_polling(non_stop=non_stop, interval=interval, timeout=timeout, long_polling_timeout=long_polling_timeout,
  File "/data/data/com.termux/files/usr/lib/python3.12/site-packages/telebot/__init__.py", line 1273, in __threaded_polling
    raise e
  File "/data/data/com.termux/files/usr/lib/python3.12/site-packages/telebot/__init__.py", line 1234, in __threaded_polling
    polling_thread.raise_exceptions()
  File "/data/data/com.termux/files/usr/lib/python3.12/site-packages/telebot/util.py", line 111, in raise_exceptions
    raise self.exception_info
  File "/data/data/com.termux/files/usr/lib/python3.12/site-packages/telebot/util.py", line 93, in run
    task(*args, **kwargs)
  File "/data/data/com.termux/files/usr/lib/python3.12/site-packages/telebot/__init__.py", line 688, in __retrieve_updates
    updates = self.get_updates(offset=(self.last_update_id + 1), 
              ^^^^^^^^^^^^^^^^^^^^^^^^^^^^^^^^^^^^^^^^^^^^^^^^^^
  File "/data/data/com.termux/files/usr/lib/python3.12/site-packages/telebot/__init__.py", line 660, in get_updates
    json_updates = apihelper.get_updates(
                   ^^^^^^^^^^^^^^^^^^^^^^
  File "/data/data/com.termux/files/usr/lib/python3.12/site-packages/telebot/apihelper.py", line 332, in get_updates
    return _make_request(token, method_url, params=payload)
           ^^^^^^^^^^^^^^^^^^^^^^^^^^^^^^^^^^^^^^^^^^^^^^^^
  File "/data/data/com.termux/files/usr/lib/python3.12/site-packages/telebot/apihelper.py", line 162, in _make_request
    result = _get_req_session().request(
             ^^^^^^^^^^^^^^^^^^^^^^^^^^^
  File "/data/data/com.termux/files/usr/lib/python3.12/site-packages/requests/sessions.py", line 589, in request
    resp = self.send(prep, **send_kwargs)
           ^^^^^^^^^^^^^^^^^^^^^^^^^^^^^^
  File "/data/data/com.termux/files/usr/lib/python3.12/site-packages/requests/sessions.py", line 703, in send
    r = adapter.send(request, **kwargs)
        ^^^^^^^^^^^^^^^^^^^^^^^^^^^^^^^
  File "/data/data/com.termux/files/usr/lib/python3.12/site-packages/requests/adapters.py", line 682, in send
    raise ConnectionError(err, request=request)
requests.exceptions.ConnectionError: ('Connection aborted.', RemoteDisconnected('Remote end closed connection without response'))
Traceback (most recent call last):
  File "/data/data/com.termux/files/usr/lib/python3.12/site-packages/urllib3/connectionpool.py", line 787, in urlopen
    response = self._make_request(
               ^^^^^^^^^^^^^^^^^^^
  File "/data/data/com.termux/files/usr/lib/python3.12/site-packages/urllib3/connectionpool.py", line 534, in _make_request
    response = conn.getresponse()
               ^^^^^^^^^^^^^^^^^^
  File "/data/data/com.termux/files/usr/lib/python3.12/site-packages/urllib3/connection.py", line 565, in getresponse
    httplib_response = super().getresponse()
                       ^^^^^^^^^^^^^^^^^^^^^
  File "/data/data/com.termux/files/usr/lib/python3.12/http/client.py", line 1430, in getresponse
    response.begin()
  File "/data/data/com.termux/files/usr/lib/python3.12/http/client.py", line 331, in begin
    version, status, reason = self._read_status()
                              ^^^^^^^^^^^^^^^^^^^
  File "/data/data/com.termux/files/usr/lib/python3.12/http/client.py", line 300, in _read_status
    raise RemoteDisconnected("Remote end closed connection without"
http.client.RemoteDisconnected: Remote end closed connection without response

During handling of the above exception, another exception occurred:

Traceback (most recent call last):
  File "/data/data/com.termux/files/usr/lib/python3.12/site-packages/requests/adapters.py", line 667, in send
    resp = conn.urlopen(
           ^^^^^^^^^^^^^
  File "/data/data/com.termux/files/usr/lib/python3.12/site-packages/urllib3/connectionpool.py", line 841, in urlopen
    retries = retries.increment(
              ^^^^^^^^^^^^^^^^^^
  File "/data/data/com.termux/files/usr/lib/python3.12/site-packages/urllib3/util/retry.py", line 474, in increment
    raise reraise(type(error), error, _stacktrace)
          ^^^^^^^^^^^^^^^^^^^^^^^^^^^^^^^^^^^^^^^^
  File "/data/data/com.termux/files/usr/lib/python3.12/site-packages/urllib3/util/util.py", line 38, in reraise
    raise value.with_traceback(tb)
  File "/data/data/com.termux/files/usr/lib/python3.12/site-packages/urllib3/connectionpool.py", line 787, in urlopen
    response = self._make_request(
               ^^^^^^^^^^^^^^^^^^^
  File "/data/data/com.termux/files/usr/lib/python3.12/site-packages/urllib3/connectionpool.py", line 534, in _make_request
    response = conn.getresponse()
               ^^^^^^^^^^^^^^^^^^
  File "/data/data/com.termux/files/usr/lib/python3.12/site-packages/urllib3/connection.py", line 565, in getresponse
    httplib_response = super().getresponse()
                       ^^^^^^^^^^^^^^^^^^^^^
  File "/data/data/com.termux/files/usr/lib/python3.12/http/client.py", line 1430, in getresponse
    response.begin()
  File "/data/data/com.termux/files/usr/lib/python3.12/http/client.py", line 331, in begin
    version, status, reason = self._read_status()
                              ^^^^^^^^^^^^^^^^^^^
  File "/data/data/com.termux/files/usr/lib/python3.12/http/client.py", line 300, in _read_status
    raise RemoteDisconnected("Remote end closed connection without"
urllib3.exceptions.ProtocolError: ('Connection aborted.', RemoteDisconnected('Remote end closed connection without response'))

During handling of the above exception, another exception occurred:

Traceback (most recent call last):
  File "/data/data/com.termux/files/home/storage/downloads/telegram_bot/bot.py", line 37, in <module>
    bot.polling()
  File "/data/data/com.termux/files/usr/lib/python3.12/site-packages/telebot/__init__.py", line 1198, in polling
    self.__threaded_polling(non_stop=non_stop, interval=interval, timeout=timeout, long_polling_timeout=long_polling_timeout,
  File "/data/data/com.termux/files/usr/lib/python3.12/site-packages/telebot/__init__.py", line 1273, in __threaded_polling
    raise e
  File "/data/data/com.termux/files/usr/lib/python3.12/site-packages/telebot/__init__.py", line 1234, in __threaded_polling
    polling_thread.raise_exceptions()
  File "/data/data/com.termux/files/usr/lib/python3.12/site-packages/telebot/util.py", line 111, in raise_exceptions
    raise self.exception_info
  File "/data/data/com.termux/files/usr/lib/python3.12/site-packages/telebot/util.py", line 93, in run
    task(*args, **kwargs)
  File "/data/data/com.termux/files/usr/lib/python3.12/site-packages/telebot/__init__.py", line 688, in __retrieve_updates
    updates = self.get_updates(offset=(self.last_update_id + 1), 
              ^^^^^^^^^^^^^^^^^^^^^^^^^^^^^^^^^^^^^^^^^^^^^^^^^^
  File "/data/data/com.termux/files/usr/lib/python3.12/site-packages/telebot/__init__.py", line 660, in get_updates
    json_updates = apihelper.get_updates(
                   ^^^^^^^^^^^^^^^^^^^^^^
  File "/data/data/com.termux/files/usr/lib/python3.12/site-packages/telebot/apihelper.py", line 332, in get_updates
    return _make_request(token, method_url, params=payload)
           ^^^^^^^^^^^^^^^^^^^^^^^^^^^^^^^^^^^^^^^^^^^^^^^^
  File "/data/data/com.termux/files/usr/lib/python3.12/site-packages/telebot/apihelper.py", line 162, in _make_request
    result = _get_req_session().request(
             ^^^^^^^^^^^^^^^^^^^^^^^^^^^
  File "/data/data/com.termux/files/usr/lib/python3.12/site-packages/requests/sessions.py", line 589, in request
    resp = self.send(prep, **send_kwargs)
           ^^^^^^^^^^^^^^^^^^^^^^^^^^^^^^
  File "/data/data/com.termux/files/usr/lib/python3.12/site-packages/requests/sessions.py", line 703, in send
    r = adapter.send(request, **kwargs)
        ^^^^^^^^^^^^^^^^^^^^^^^^^^^^^^^
  File "/data/data/com.termux/files/usr/lib/python3.12/site-packages/requests/adapters.py", line 682, in send
    raise ConnectionError(err, request=request)
requests.exceptions.ConnectionError: ('Connection aborted.', RemoteDisconnected('Remote end closed connection without response'))
